[2022-12-11T15:17:57.944+0000] {taskinstance.py:1165} INFO - Dependencies all met for <TaskInstance: mongo_etl.companies_mongo manual__2022-12-11T15:14:26.289699+00:00 [queued]>
[2022-12-11T15:17:58.320+0000] {taskinstance.py:1165} INFO - Dependencies all met for <TaskInstance: mongo_etl.companies_mongo manual__2022-12-11T15:14:26.289699+00:00 [queued]>
[2022-12-11T15:17:58.327+0000] {taskinstance.py:1362} INFO - 
--------------------------------------------------------------------------------
[2022-12-11T15:17:58.333+0000] {taskinstance.py:1363} INFO - Starting attempt 1 of 1
[2022-12-11T15:17:58.334+0000] {taskinstance.py:1364} INFO - 
--------------------------------------------------------------------------------
[2022-12-11T15:17:58.993+0000] {taskinstance.py:1383} INFO - Executing <Task(BashOperator): companies_mongo> on 2022-12-11 15:14:26.289699+00:00
[2022-12-11T15:17:59.113+0000] {standard_task_runner.py:55} INFO - Started process 1860 to run task
[2022-12-11T15:17:59.233+0000] {standard_task_runner.py:82} INFO - Running: ['***', 'tasks', 'run', 'mongo_etl', 'companies_mongo', 'manual__2022-12-11T15:14:26.289699+00:00', '--job-id', '38', '--raw', '--subdir', 'DAGS_FOLDER/mongo_etl/mongo_dags.py', '--cfg-path', '/tmp/tmpa9hjzlut']
[2022-12-11T15:17:59.295+0000] {standard_task_runner.py:83} INFO - Job 38: Subtask companies_mongo
[2022-12-11T15:18:00.946+0000] {task_command.py:376} INFO - Running <TaskInstance: mongo_etl.companies_mongo manual__2022-12-11T15:14:26.289699+00:00 [running]> on host 90ebd458857e
[2022-12-11T15:18:03.123+0000] {taskinstance.py:1590} INFO - Exporting the following env vars:
AIRFLOW_CTX_DAG_OWNER=***
AIRFLOW_CTX_DAG_ID=mongo_etl
AIRFLOW_CTX_TASK_ID=companies_mongo
AIRFLOW_CTX_EXECUTION_DATE=2022-12-11T15:14:26.289699+00:00
AIRFLOW_CTX_TRY_NUMBER=1
AIRFLOW_CTX_DAG_RUN_ID=manual__2022-12-11T15:14:26.289699+00:00
[2022-12-11T15:18:03.177+0000] {subprocess.py:63} INFO - Tmp dir root location: 
 /tmp
[2022-12-11T15:18:03.212+0000] {subprocess.py:75} INFO - Running command: ['/bin/bash', '-c', 'python3 /home/fajarsetia/Documents/de9-final-project-main/mongo_etl/companies/companies.py']
[2022-12-11T15:18:03.560+0000] {subprocess.py:86} INFO - Output:
[2022-12-11T15:18:04.391+0000] {base_job.py:232} ERROR - LocalTaskJob heartbeat got an exception
Traceback (most recent call last):
  File "/home/airflow/.local/lib/python3.8/site-packages/sqlalchemy/engine/base.py", line 3243, in _wrap_pool_connect
    return fn()
  File "/home/airflow/.local/lib/python3.8/site-packages/sqlalchemy/pool/base.py", line 310, in connect
    return _ConnectionFairy._checkout(self)
  File "/home/airflow/.local/lib/python3.8/site-packages/sqlalchemy/pool/base.py", line 868, in _checkout
    fairy = _ConnectionRecord.checkout(pool)
  File "/home/airflow/.local/lib/python3.8/site-packages/sqlalchemy/pool/base.py", line 476, in checkout
    rec = pool._do_get()
  File "/home/airflow/.local/lib/python3.8/site-packages/sqlalchemy/pool/impl.py", line 256, in _do_get
    return self._create_connection()
  File "/home/airflow/.local/lib/python3.8/site-packages/sqlalchemy/pool/base.py", line 256, in _create_connection
    return _ConnectionRecord(self)
  File "/home/airflow/.local/lib/python3.8/site-packages/sqlalchemy/pool/base.py", line 371, in __init__
    self.__connect()
  File "/home/airflow/.local/lib/python3.8/site-packages/sqlalchemy/pool/base.py", line 666, in __connect
    pool.logger.debug("Error on connect(): %s", e)
  File "/home/airflow/.local/lib/python3.8/site-packages/sqlalchemy/util/langhelpers.py", line 70, in __exit__
    compat.raise_(
  File "/home/airflow/.local/lib/python3.8/site-packages/sqlalchemy/util/compat.py", line 207, in raise_
    raise exception
  File "/home/airflow/.local/lib/python3.8/site-packages/sqlalchemy/pool/base.py", line 661, in __connect
    self.dbapi_connection = connection = pool._invoke_creator(self)
  File "/home/airflow/.local/lib/python3.8/site-packages/sqlalchemy/engine/create.py", line 590, in connect
    return dialect.connect(*cargs, **cparams)
  File "/home/airflow/.local/lib/python3.8/site-packages/sqlalchemy/engine/default.py", line 584, in connect
    return self.dbapi.connect(*cargs, **cparams)
  File "/home/airflow/.local/lib/python3.8/site-packages/psycopg2/__init__.py", line 122, in connect
    conn = _connect(dsn, connection_factory=connection_factory, **kwasync)
psycopg2.OperationalError: connection to server at "postgres" (172.18.0.2), port 5432 failed: FATAL:  password authentication failed for user "***"


The above exception was the direct cause of the following exception:

Traceback (most recent call last):
  File "/home/airflow/.local/lib/python3.8/site-packages/airflow/jobs/base_job.py", line 204, in heartbeat
    session.merge(self)
  File "/home/airflow/.local/lib/python3.8/site-packages/sqlalchemy/orm/session.py", line 2955, in merge
    return self._merge(
  File "/home/airflow/.local/lib/python3.8/site-packages/sqlalchemy/orm/session.py", line 3035, in _merge
    merged = self.get(
  File "/home/airflow/.local/lib/python3.8/site-packages/sqlalchemy/orm/session.py", line 2768, in get
    return self._get_impl(
  File "/home/airflow/.local/lib/python3.8/site-packages/sqlalchemy/orm/session.py", line 2874, in _get_impl
    return db_load_fn(
  File "/home/airflow/.local/lib/python3.8/site-packages/sqlalchemy/orm/loading.py", line 530, in load_on_pk_identity
    session.execute(
  File "/home/airflow/.local/lib/python3.8/site-packages/sqlalchemy/orm/session.py", line 1688, in execute
    conn = self._connection_for_bind(bind)
  File "/home/airflow/.local/lib/python3.8/site-packages/sqlalchemy/orm/session.py", line 1529, in _connection_for_bind
    return self._transaction._connection_for_bind(
  File "/home/airflow/.local/lib/python3.8/site-packages/sqlalchemy/orm/session.py", line 747, in _connection_for_bind
    conn = bind.connect()
  File "/home/airflow/.local/lib/python3.8/site-packages/sqlalchemy/engine/base.py", line 3197, in connect
    return self._connection_cls(self, close_with_result=close_with_result)
  File "/home/airflow/.local/lib/python3.8/site-packages/sqlalchemy/engine/base.py", line 96, in __init__
    else engine.raw_connection()
  File "/home/airflow/.local/lib/python3.8/site-packages/sqlalchemy/engine/base.py", line 3276, in raw_connection
    return self._wrap_pool_connect(self.pool.connect, _connection)
  File "/home/airflow/.local/lib/python3.8/site-packages/sqlalchemy/engine/base.py", line 3246, in _wrap_pool_connect
    Connection._handle_dbapi_exception_noconnection(
  File "/home/airflow/.local/lib/python3.8/site-packages/sqlalchemy/engine/base.py", line 2100, in _handle_dbapi_exception_noconnection
    util.raise_(
  File "/home/airflow/.local/lib/python3.8/site-packages/sqlalchemy/util/compat.py", line 207, in raise_
    raise exception
  File "/home/airflow/.local/lib/python3.8/site-packages/sqlalchemy/engine/base.py", line 3243, in _wrap_pool_connect
    return fn()
  File "/home/airflow/.local/lib/python3.8/site-packages/sqlalchemy/pool/base.py", line 310, in connect
    return _ConnectionFairy._checkout(self)
  File "/home/airflow/.local/lib/python3.8/site-packages/sqlalchemy/pool/base.py", line 868, in _checkout
    fairy = _ConnectionRecord.checkout(pool)
  File "/home/airflow/.local/lib/python3.8/site-packages/sqlalchemy/pool/base.py", line 476, in checkout
    rec = pool._do_get()
  File "/home/airflow/.local/lib/python3.8/site-packages/sqlalchemy/pool/impl.py", line 256, in _do_get
    return self._create_connection()
  File "/home/airflow/.local/lib/python3.8/site-packages/sqlalchemy/pool/base.py", line 256, in _create_connection
    return _ConnectionRecord(self)
  File "/home/airflow/.local/lib/python3.8/site-packages/sqlalchemy/pool/base.py", line 371, in __init__
    self.__connect()
  File "/home/airflow/.local/lib/python3.8/site-packages/sqlalchemy/pool/base.py", line 666, in __connect
    pool.logger.debug("Error on connect(): %s", e)
  File "/home/airflow/.local/lib/python3.8/site-packages/sqlalchemy/util/langhelpers.py", line 70, in __exit__
    compat.raise_(
  File "/home/airflow/.local/lib/python3.8/site-packages/sqlalchemy/util/compat.py", line 207, in raise_
    raise exception
  File "/home/airflow/.local/lib/python3.8/site-packages/sqlalchemy/pool/base.py", line 661, in __connect
    self.dbapi_connection = connection = pool._invoke_creator(self)
  File "/home/airflow/.local/lib/python3.8/site-packages/sqlalchemy/engine/create.py", line 590, in connect
    return dialect.connect(*cargs, **cparams)
  File "/home/airflow/.local/lib/python3.8/site-packages/sqlalchemy/engine/default.py", line 584, in connect
    return self.dbapi.connect(*cargs, **cparams)
  File "/home/airflow/.local/lib/python3.8/site-packages/psycopg2/__init__.py", line 122, in connect
    conn = _connect(dsn, connection_factory=connection_factory, **kwasync)
sqlalchemy.exc.OperationalError: (psycopg2.OperationalError) connection to server at "postgres" (172.18.0.2), port 5432 failed: FATAL:  password authentication failed for user "***"

(Background on this error at: https://sqlalche.me/e/14/e3q8)
[2022-12-11T15:18:07.625+0000] {subprocess.py:93} INFO - python3: can't open file '/home/fajarsetia/Documents/de9-final-project-main/mongo_etl/companies/companies.py': [Errno 2] No such file or directory
[2022-12-11T15:18:07.766+0000] {subprocess.py:97} INFO - Command exited with return code 2
[2022-12-11T15:18:07.933+0000] {taskinstance.py:1851} ERROR - Task failed with exception
Traceback (most recent call last):
  File "/home/airflow/.local/lib/python3.8/site-packages/airflow/operators/bash.py", line 196, in execute
    raise AirflowException(
airflow.exceptions.AirflowException: Bash command failed. The command returned a non-zero exit code 2.
[2022-12-11T15:18:08.048+0000] {taskinstance.py:1401} INFO - Marking task as FAILED. dag_id=mongo_etl, task_id=companies_mongo, execution_date=20221211T151426, start_date=20221211T151757, end_date=20221211T151808
[2022-12-11T15:18:08.611+0000] {standard_task_runner.py:100} ERROR - Failed to execute job 38 for task companies_mongo (Bash command failed. The command returned a non-zero exit code 2.; 1860)
[2022-12-11T15:18:08.940+0000] {local_task_job.py:159} INFO - Task exited with return code 1
[2022-12-11T15:18:09.682+0000] {taskinstance.py:2623} INFO - 0 downstream tasks scheduled from follow-on schedule check
